<?xml version="1.0"?>
<robot name="turtlebot3_waffle_pi_3d" xmlns:xacro="http://ros.org/wiki/xacro">

  <!-- 基本底盘 -->
  <link name="base_footprint"/>

  <link name="base_link">
    <inertial>
      <mass value="1.5" />
      <origin xyz="0 0 0.05" />
      <inertia ixx="0.1" ixy="0" ixz="0" iyy="0.1" iyz="0" izz="0.2" />
    </inertial>
    
    <visual>
      <origin xyz="0 0 0.05" rpy="0 0 0" />
      <geometry>
        <box size="0.2 0.2 0.1" />
      </geometry>
      <material name="Blue">
        <color rgba="0 0 0.8 1" />
      </material>
    </visual>
    
    <collision>
      <origin xyz="0 0 0.05" rpy="0 0 0" />
      <geometry>
        <box size="0.2 0.2 0.1" />
      </geometry>
    </collision>
  </link>

  <joint name="base_footprint_joint" type="fixed">
    <origin xyz="0 0 0.05" rpy="0 0 0" />
    <parent link="base_footprint" />
    <child link="base_link" />
  </joint>

  <!-- 左轮 -->
  <link name="left_wheel">
    <inertial>
      <mass value="0.1" />
      <origin xyz="0 0 0" />
      <inertia ixx="0.001" ixy="0" ixz="0" iyy="0.001" iyz="0" izz="0.001" />
    </inertial>
    
    <visual>
      <origin xyz="0 0 0" rpy="1.5708 0 0" />
      <geometry>
        <cylinder length="0.02" radius="0.05" />
      </geometry>
      <material name="Black">
        <color rgba="0 0 0 1" />
      </material>
    </visual>
  </link>

  <joint name="left_wheel_joint" type="continuous">
    <origin xyz="0 0.1 -0.05" rpy="0 0 0" />
    <parent link="base_link" />
    <child link="left_wheel" />
    <axis xyz="0 1 0" />
  </joint>

  <!-- 右轮 -->
  <link name="right_wheel">
    <inertial>
      <mass value="0.1" />
      <origin xyz="0 0 0" />
      <inertia ixx="0.001" ixy="0" ixz="0" iyy="0.001" iyz="0" izz="0.001" />
    </inertial>
    
    <visual>
      <origin xyz="0 0 0" rpy="1.5708 0 0" />
      <geometry>
        <cylinder length="0.02" radius="0.05" />
      </geometry>
      <material name="Black">
        <color rgba="0 0 0 1" />
      </material>
    </visual>
  </link>

  <joint name="right_wheel_joint" type="continuous">
    <origin xyz="0 -0.1 -0.05" rpy="0 0 0" />
    <parent link="base_link" />
    <child link="right_wheel" />
    <axis xyz="0 1 0" />
  </joint>

  <!-- 3D雷达 -->
  <link name="velodyne_link">
    <inertial>
      <mass value="0.1" />
      <origin xyz="0 0 0" />
      <inertia ixx="0.001" ixy="0" ixz="0" iyy="0.001" iyz="0" izz="0.001" />
    </inertial>
    
    <visual>
      <origin xyz="0 0 0" rpy="0 0 0" />
      <geometry>
        <cylinder length="0.1" radius="0.05" />
      </geometry>
      <material name="Grey">
        <color rgba="0.5 0.5 0.5 1" />
      </material>
    </visual>
  </link>

  <joint name="velodyne_joint" type="fixed">
    <origin xyz="0.1 0 0.2" rpy="0 0 0" />
    <parent link="base_link" />
    <child link="velodyne_link" />
  </joint>

  <!-- Gazebo插件部分 -->
  <gazebo>
    <!-- 差分驱动控制器 -->
    <plugin name="differential_drive_controller" filename="libgazebo_ros_diff_drive.so">
      <ros>
        <namespace>/</namespace>
      </ros>
      <robot_namespace>/</robot_namespace>
      <publish_odom>true</publish_odom>
      <publish_odom_tf>true</publish_odom_tf>
      <publish_wheel_tf>true</publish_wheel_tf>
      <odometry_frame>odom</odometry_frame>
      <robot_base_frame>base_footprint</robot_base_frame>
      <left_joint>left_wheel_joint</left_joint>
      <right_joint>right_wheel_joint</right_joint>
      <wheel_separation>0.2</wheel_separation>
      <wheel_diameter>0.1</wheel_diameter>
      <wheel_acceleration>1.0</wheel_acceleration>
      <wheel_torque>10.0</wheel_torque>
      <odometry_source>world</odometry_source>
      <command_topic>cmd_vel</command_topic>
      <odometry_topic>odom</odometry_topic>
      <publish_odometry_msg>true</publish_odometry_msg>
    </plugin>
  </gazebo>

  <!-- 3D雷达传感器（修正噪声配置） -->
  <gazebo reference="velodyne_link">
    <sensor type="ray" name="velodyne_sensor">
      <pose>0 0 0 0 0 0</pose>
      <visualize>true</visualize>
      <update_rate>10</update_rate>
      <ray>
        <scan>
          <horizontal>
            <samples>360</samples>
            <resolution>1.0</resolution>
            <min_angle>-3.14159</min_angle>
            <max_angle>3.14159</max_angle>
          </horizontal>
          <vertical>
            <samples>16</samples>
            <resolution>1.0</resolution>
            <min_angle>-0.261799</min_angle>
            <max_angle>0.261799</max_angle>
          </vertical>
        </scan>
        <range>
          <min>0.1</min>
          <max>30.0</max>
          <resolution>0.01</resolution>
        </range>
        <!-- 修正噪声配置 -->
        <noise>
          <type>gaussian</type>
        </noise>
      </ray>
      <plugin name="gazebo_ros_laser" filename="libgazebo_ros_ray_sensor.so">
        <topic_name>/velodyne_points</topic_name>
        <frame_name>velodyne_link</frame_name>
      </plugin>
    </sensor>
  </gazebo>

  <!-- 左相机 -->
  <link name="left_camera_link">
    <inertial>
      <mass value="0.05" />
      <origin xyz="0 0 0" />
      <inertia ixx="0.0001" ixy="0" ixz="0" iyy="0.0001" iyz="0" izz="0.0001" />
    </inertial>
    
    <visual>
      <origin xyz="0 0 0" rpy="0 0 0" />
      <geometry>
        <box size="0.05 0.05 0.05" />
      </geometry>
      <material name="Red">
        <color rgba="1 0 0 1" />
      </material>
    </visual>
  </link>

  <joint name="left_camera_joint" type="fixed">
    <origin xyz="0.15 0.05 0.1" rpy="0 0.1 0" />
    <parent link="base_link" />
    <child link="left_camera_link" />
  </joint>

  <!-- 相机传感器（修正噪声配置） -->
  <gazebo reference="left_camera_link">
    <sensor type="camera" name="left_camera_sensor">
      <update_rate>30.0</update_rate>
      <camera name="left_camera">
        <horizontal_fov>1.3962634</horizontal_fov>
        <image>
          <width>640</width>
          <height>480</height>
          <format>R8G8B8</format>
        </image>
        <clip>
          <near>0.02</near>
          <far>300</far>
        </clip>
        <!-- 修正噪声配置 -->
        <noise>
          <type>gaussian</type>
        </noise>
      </camera>
      <plugin name="camera_controller" filename="libgazebo_ros_camera.so">
        <ros>
          <namespace>/</namespace>
        </ros>
        <camera_name>left_camera</camera_name>
        <frame_name>left_camera_link</frame_name>
      </plugin>
    </sensor>
  </gazebo>

  <!-- IMU（用于fast-livo2） -->
  <link name="imu_link">
    <inertial>
      <mass value="0.01" />
      <origin xyz="0 0 0" />
      <inertia ixx="0.00001" ixy="0" ixz="0" iyy="0.00001" iyz="0" izz="0.00001" />
    </inertial>
    
    <visual>
      <origin xyz="0 0 0" rpy="0 0 0" />
      <geometry>
        <box size="0.02 0.02 0.02" />
      </geometry>
      <material name="Green">
        <color rgba="0 1 0 1" />
      </material>
    </visual>
  </link>

  <joint name="imu_joint" type="fixed">
    <origin xyz="0.0 0 0.1" rpy="0 0 0" />
    <parent link="base_link" />
    <child link="imu_link" />
  </joint>

  <!-- IMU传感器（修正配置） -->
  <gazebo reference="imu_link">
    <sensor type="imu" name="imu_sensor">
      <always_on>true</always_on>
      <update_rate>100</update_rate>
      <visualize>true</visualize>
      <plugin name="imu_plugin" filename="libgazebo_ros_imu_sensor.so">
        <ros>
          <namespace>/</namespace>
        </ros>
        <topic_name>imu</topic_name>
        <body_name>imu_link</body_name>
        <update_rate>100</update_rate>
        <gravity_z>9.81</gravity_z>
        <xyz_offset>0 0 0</xyz_offset>
        <rpy_offset>0 0 0</rpy_offset>
        <frame_name>imu_link</frame_name>
        <initial_orientation_as_reference>false</initial_orientation_as_reference>
      </plugin>
    </sensor>
  </gazebo>

</robot>
